Workbook
Name Agency_data: 'ODEM data'!$A$2:$E$254
Name Buck_Creek: #REF!
Name County: Counties!$A$3:$B$38
Name DailyLog: 'Daily Metrics Log'!$A$2:$J$2000
Name Fires: '[1]Property Loss'!$A$5:$A$107
Name Fires: 'NWCC Fire Data'!$A$1:$T$5025
Name Fires_2025: 'NWCC Fire Data'!$B$179:$B$369
Name ODEM: 'ODEM data'!$C$2:$E$2057
Name ODF: 'ODF data'!$A$3:$I$23
Name Slicer_Misc: #N/A
Name Slicer_Year: #N/A
Name Slicer_Year1: #N/A
Name Wildfires: 'NWCC Fire Data'!$A$1:$T$107
Name Wiley_Flat: #REF!

Sheet ODEM data
A1: Year | B1: Agency | C1: ODEM report date | D1: ODEM Active fires | E1: ODEM Acres burned | F1: Note
A2: 2024 | B2: ODEM | C2: 45468 | D2: 22 | E2: 1885
A3: 2024 | B3: ODEM | C3: 45469 | D3: 39 | E3: 4392
A4: 2024 | B4: ODEM | C4: 45470 | D4: 44 | E4: 20010
A5: 2024 | B5: ODEM | C5: 45471 | D5: 39 | E5: 24110
A6: 2024 | B6: ODEM | C6: 45474 | D6: 20 | E6: 24018
A7: 2024 | B7: ODEM | C7: 45475 | D7: 20 | E7: 24011
A8: 2024 | B8: ODEM | C8: 45476 | D8: 22 | E8: 24011
A9: 2024 | B9: ODEM | C9: 45478 | D9: 35 | E9: 24110
A10: 2024 | B10: ODEM | C10: 45481 | D10: 29 | E10: 20680
A11: 2024 | B11: ODEM | C11: 45482 | D11: 24 | E11: 5484
A12: 2024 | B12: ODEM | C12: 45483 | D12: 21 | E12: 14369
A13: 2024 | B13: ODEM | C13: 45484 | D13: 29 | E13: 25284
... A82: 2024 | B82: ODEM | C82: 45582 | D82: 80 | E82: 388380
A83: 2024 | B83: ODEM | C83: 45583 | D83: 78 | E83: 415194 | F83: Last report of season (DFR)
A84: 2024 | B84: ODEM | C84: 45610 | D84: 14 | E84: 27290
A85: 2024 | B85: ODEM | C85: 45611 | D85: 13 | E85: 26762
A86: 2024 | B86: ODEM | C86: 45614 | D86: 7 | E86: 23829
A87: 2024 | B87: ODEM | C87: 45615 | D87: 6 | E87: 21748
A88: 2024 | B88: ODEM | C88: 45616 | D88: 7 | E88: 21773
A89: 2024 | B89: ODEM | C89: 45617 | D89: 23 | E89: 28399
A90: 2024 | B90: ODEM | C90: 45618 | D90: 33 | E90: 34825
A91: 2024 | B91: ODEM | C91: 45621 | D91: 12 | E91: 29443
A92: 2024 | B92: ODEM | C92: 45623 | D92: 11 | E92: 29374
A93: 2024 | B93: ODEM | C93: 45628 | D93: 5 | E93: 13000
A94: 2024 | B94: ODEM | C94: 45629 | D94: 6 | E94: 13000
A95: 2024 | B95: ODEM | C95: 45630 | D95: 9 | E95: 13001
... A129: 2025 | B129: ODEM | C129: 45686 | D129: 1 | E129: 25972
A130: 2025 | B130: ODEM | C130: 45687 | D130: 1 | F130: last update 1/29 at 1:08pm
A131: 2025 | B131: ODEM | C131: 45688 | D131: 1 | F131: last update 1/29 at 1:08pm
A132: 2025 | B132: ODEM | C132: 45691 | D132: 0
A133: 2025 | B133: ODEM | C133: 45692 | D133: 0
A134: 2025 | B134: ODEM | C134: 45693 | D134: 0
A135: 2025 | B135: ODEM | C135: 45694 | D135: 0
A136: 2025 | B136: ODEM | C136: 45695 | D136: 0
A137: 2025 | B137: ODEM | C137: 45698 | D137: 0
A138: 2025 | B138: ODEM | C138: 45699 | D138: 1 | E138: 65
A139: 2025 | B139: ODEM | C139: 45700 | D139: 1 | E139: 65
A140: 2025 | B140: ODEM | C140: 45701 | D140: 1 | E140: 65
A141: 2025 | B141: ODEM | C141: 45702 | D141: 2 | E141: 65
...

Sheet NWCC Fire Data
A1: Year | B1: Name | C1: County | D1: Size | E1: Containment | F1: Location | G1: Level 1 | H1: Level 2 | I1: Level 3 | J1: Res-threat | K1: Comm-threat | L1: Minor-threat | M1: Res-des | N1: Com-des | O1: Minor-des | P1: RV as home | Q1: Fatalities | R1: Injuries | S1: Misc | T1: Status | U1: Note
A2: 2020 | B2: Lionshead | C2: Marion | D2: 204469 | E2: 1 | M2: 264 | S2: T | T2: Cont | U2: combined with beachie
A3: 2020 | B3: Beachie | C3: Marion | D3: 193566 | E3: 1 | F3: 6.6 Miles N of Detroit | M3: 436 | S3: TLA | T3: Cont | U3: ~230 2nd resdiences lost
A4: 2020 | B4: Holiday Farm | C4: Lane | D4: 173393 | E4: 1 | F4: 3 miles west of McKenzie Bridg | M4: 431 | O4: 24 | T4: Cont
A5: 2020 | B5: Illinois Valley Support | C5: Yamhill | D5: 152270 | E5: 1 | F5: O'Brien | T5: Cont
A6: 2020 | B6: Riverside (ODF) | C6: Clackamas | D6: 138054 | E6: 1 | F6: 22 Miles SE of Estacada | M6: 57 | O6: 81 | S6: T | T6: Cont
A7: 2020 | B7: Archie Creek/ Star Mtn | C7: Douglas | D7: 130000 | E7: 1 | M7: 109 | T7: Cont
A8: 2020 | B8: Brattain 406 | C8: Lake | D8: 50951 | E8: 1 | F8: Brattain Butte | T8: Cont
A9: 2020 | B9: S. Obenchain | C9: Jackson | D9: 32589 | E9: 1 | F9: 6.65 miles East of Eagle Point | M9: 153 | T9: Cont | U9: Source data collected from various internet reports
A10: 2020 | B10: White River | C10: Wasco | D10: 17404.9 | E10: 1 | F10: 18 Miles West of Maupin | T10: Cont
A11: 2020 | B11: Two Four Two 404 | C11: Klamath | D11: 14473 | E11: 1 | F11: Collier State Park | S11: T | T11: Cont
A12: 2020 | B12: East Fork Butter Creek | C12: Umatilla | D12: 12756 | E12: 1 | F12: East Fork Butter Creek | T12: Cont
A13: 2020 | B13: GREEN RIDGE 0684 | C13: Jefferson | D13: 4338 | E13: 1 | F13: 10 MILES NORTH OF SISTERS | T13: Cont
A14: 2020 | B14: Baldy | C14: Malheur | D14: 3703 | E14: 1 | T14: Cont
A15: 2020 | B15: Almeda | C15: Jackson | D15: 3200 | E15: 1 | F15: Ashland Creek | M15: 2194 | O15: 443 | S15: T | T15: Cont | U15: Source data collected from various internet reports
A16: 2020 | B16: Crane 345 | C16: Lake | D16: 2993 | E16: 1 | F16: Crane Mountain | T16: Cont
A17: 2020 | B17: Echo Mountain | C17: Lincoln | D17: 1879.01 | E17: 1 | F17: 6.04 miles NE of Lincoln City | M17: 300 | T17: Cont | U17: Sourced from internet reports. Est.
A18: 2020 | B18: Dowty Rd | C18: Clackamas | D18: 1509 | E18: 1 | F18: Near Eagle Creek | T18: Cont
A19: 2020 | B19: Laurel | C19: Wheeler | D19: 1280 | E19: 1 | T19: Cont
A20: 2020 | B20: Ben Young 196 | C20: Lake | D20: 1249 | E20: 1 | F20: Round Mountain | T20: Cont
A21: 2020 | B21: Mosier Creek | C21: Wasco | D21: 985 | E21: 1 | F21: 2 Miles SE of Mosier | T21: Cont
A22: 2020 | B22: Teller Flats 0281 OD | C22: Crook | D22: 946 | E22: 1 | F22: 20 miles North of Prineville | T22: Cont
A23: 2020 | B23: Worthington | C23: Jackson | D23: 761 | E23: 1 | F23: 5.39 miles Northeast of Eagle | T23: Cont
A24: 2020 | B24: Steet Mountain | C24: Grant | D24: 680 | E24: 1 | F24: 5.7 miles NE of Monument | T24: Cont
A25: 2020 | B25: Ritter | C25: Grant | D25: 676 | E25: 1 | F25: 7.1 Mi. North of Long Creek | T25: Cont
A26: 2020 | B26: Wilhoit | C26: Clackamas | D26: 532 | E26: 1 | F26: Wilhoit Rd | T26: Cont
A27: 2020 | B27: Unger Rd | C27: Clackamas | D27: 497 | E27: 1 | F27: 2.5 Mi NE of Colton | T27: Cont
A28: 2020 | B28: French Creek | C28: Douglas | D28: 495 | E28: 1 | T28: Cont
A29: 2020 | B29: Grizzly Creek | C29: Jackson | D29: 323 | E29: 1 | F29: 16.32 miles East of Ashland | T29: Cont
A30: 2020 | B30: North Bank Lane MM8 | C30: Coos | D30: 319 | E30: 1 | F30: 5 E Bandon | T30: Cont
A31: 2020 | B31: Fir Mountain | C31: Hood River | D31: 313 | E31: 1 | F31: 8 Miles SW of Mosier | T31: Cont
A32: 2020 | B32: Sweet Creek MP 2 | C32: Lane | D32: 307 | E32: 1 | F32: Mapleton Landing County Park, | T32: Cont
A33: 2020 | B33: Pike Road | C33: Tillamook | D33: 301 | E33: 1 | F33: 2 miles E Bay City | T33: Cont
A34: 2020 | B34: Dry Gulch | C34: Baker | D34: 297 | E34: 1 | T34: Cont
A35: 2020 | B35: Kimberling Mt | C35: Lincoln | D35: 281.75 | E35: 1 | F35: 9.34 miles E of Lincoln City | T35: Cont
A36: 2020 | B36: Buckhorn Creek | C36: Wheeler | D36: 233 | E36: 1 | F36: 12.2 miles NW of Dayville | T36: Cont
A37: 2020 | B37: Horse | C37: Umatilla | D37: 169.5 | E37: 1 | F37: Horse Ridge | T37: Cont
A38: 2020 | B38: Haystack | C38: Wheeler | D38: 117 | E38: 1 | F38: 4.4 miles N.E. spray | T38: Cont
A39: 2020 | B39: War Canyon | C39: Grant | D39: 112.3 | E39: 1 | F39: 4.3 miles E of Long Creek | T39: Cont
A40: 2020 | B40: Greenway MM 24.2 | C40: Jackson | D40: 105 | E40: 1 | F40: Bear Creek | T40: Cont
...

Sheet MAPS
A2: Air Quality Monitor from OEM dashboard | F2: 7/15/2026, 7:32am | J2: Northwest Large Fire Map | O2: 7/15/2026, 7:45am
A4: #VALUE! | J4: https://wfca.com/fire-map?lng=-120.5834&lat=44.1849&zoom=6.35

Sheet Chart-acres vs active
A1: Year | B1: 2026
A2: =B1 -> 2026 | B2: Acres burned vs. Active fires
A3: Row Labels | B3: Active Fires | AA3: =CONCATENATE(AA4,AB4) -> 2026 Wildfire Season - Acres burned and Active Fires, by Date
A4: (blank) | AA4: =B1 -> 2026 | AB4: Wildfire Season - Acres burned and Active Fires, by Date
A5: 46023 | B5: 1
A6: 46024 | B6: 1
A7: 46027 | B7: 15
A8: 46028 | B8: 10
A9: 46029 | B9: 19
A10: 46030 | B10: 23
A11: 46031 | B11: 19
A12: 46034 | B12: 3
A13: 46036 | B13: 11
A14: 46037 | B14: 13
A15: 46038 | B15: 19
A16: 46042 | B16: 4
... A153: 46230 | B153: 92

Sheet Dashboard (2)
A1: =E3 -> 46223 | B1: Daily Wildfire Report
A2: =B23 -> 2026 | B2: Wildfire Report - by Fire Status, Name | D2: State of Oregon Fires and Hotspots Dashboard
D3: ODEM wildfire data as of | E3: 46223
A4: Note: Acres burned value reported by OEM is based on Active fires, consequently the total adjusts over time. A Large fire is any wildland fire in timber 100 acres or greater, 300 acres or greater in grasslands/rangelands, has an Incident Management Team (IMT) assigned to it, or triggers evacuations. | D4: Active fires | E4: =_xlfn.IFNA(VLOOKUP($E$3,ODEM,2,FALSE),"no data") -> 89
D5: Acres Burned (Active fires) | E5: =_xlfn.IFNA(VLOOKUP($E$3,ODEM,3,FALSE),"no data") -> 330324
D6: Active Large fires | E6: =IFERROR(GETPIVOTDATA("Name",$A$9,"Status","Large"),0) -> 37
A8: Number of tracked (large) fires by current status
B9: # of Fires | C9: Legend
A10: Large | B10: 37 | C10: Large=Active large fire
A11: Cont | B11: 23 | C11: Cont=Contained. Minimal fire activity, no more reporting
A12: PL | B12: 1 | C12: PL=Contained with property loss
A13: Grand Total | B13: 61 | C13: EVAC=Evacuations triggered, no named fire
D15: ODF Wildland Fire Situation Report | E15: updated as of | F15: =_xlfn.IFNA(VLOOKUP($B$23,ODF,3,FALSE),"no data") -> 46227 | I15: OEM Evacuation Information (Addresses)
E16: ODF Land | F16: Statewide | I16: Be Ready | J16: Be Set | K16: Go NOW | O16: R | P16: C | Q16: O | R16: RVH
D17: Active large fires | E17: =_xlfn.IFNA(VLOOKUP($B$23,ODF,4,FALSE),"no data") -> 16 | F17: =_xlfn.IFNA(VLOOKUP($B$23,ODF,7,FALSE),"no data") -> 30 | I17: 7816 | J17: 4000 | K17: 2831 | O17: 26 | Q17: 72
D18: Total fires YTD | E18: =_xlfn.IFNA(VLOOKUP($B$23,ODF,5,FALSE),"no data") -> 616 | F18: =_xlfn.IFNA(VLOOKUP($B$23,ODF,8,FALSE),"no data") -> 1238 | I18: Evacuation | O18: Structure loss
D19: Acres burned YTD | E19: =_xlfn.IFNA(VLOOKUP($B$23,ODF,6,FALSE),"no data") -> 81098 | F19: =_xlfn.IFNA(VLOOKUP($B$23,ODF,9,FALSE),"no data") -> 577106
A23: Year | B23: 2026
A24: Northwest Large Fire Information Summary -fires >100 acres timberland, >300 acres rangelend,had IMT assigned or triggered EVACs | I24: Evacuation | L24: Threatened | O24: Destroyed
F25: VALUES
A26: Status | B26: Name | C26: County | D26: Location | E26: Containment | F26: Acres burned | G26: Injuries. | H26: Fatalities. | I26: Lev 1 | J26: Lev 2 | K26: Lev 3 | L26: Residential | M26: Commercial | N26: Other | O26: Residential_ | P26: Commercial_ | Q26: Other_ | R26: RV_as_home
A27: Large | B27: 0494 Akawa Butte | C27: Jefferson | D27: 12 miles NW of Terrebone, OR | E27: 0.05 | F27: 27222 | I27: 3898 | J27: 396 | K27: 460 | L27: 4812 | O27: 2
B28: 0497 Henry | C28: Crook | D28: 5 miles S of Paulina Guard Station, OR | E28: 0.35 | F28: 28827 | L28: 8
B29: 0500 Coyote | C29: Crook | D29: 5 mile E of Coyote Butte, OR | E29: 0.57 | F29: 17447 | L29: 100
B30: 0579 Ten Mile | C30: Jefferson | D30: 2 miles NE of Gateway, OR | E30: 0.77 | F30: 4834 | L30: 30
B31: 0586 | C31: Wasco | D31: 6 miles NE of Gateway, OR | E31: 0 | F31: 191 | I31: 308 | J31: 1068 | K31: 61
B32: 0587 Shingle | C32: Wheeler | D32: 14 miles SE of Mitchell, OR | E32: 0 | F32: 53976 | I32: 0 | J32: 5 | K32: 17 | O32: 3
B33: 0611 | C33: Crook | D33: 12 miles NE of Prineville, OR | E33: 0 | F33: 2136
B34: 2680 Diamond Craters | C34: Harney | D34: 9 miles NW of Diamond, OR | E34: 0.8 | F34: 745 | L34: 15
B35: 8 Mile | C35: Wasco | D35: 8 miles W of Dufur, OR | E35: 0 | F35: 532
B36: Anthony | C36: Baker | D36: 5 miles W of Hutchinson, OR | E36: 0.89 | F36: 2550 | I36: 24 | J36: 12 | L36: 50
B37: Bald Mountain | C37: Harney | D37: 10 miles W of Diamond, OR | E37: 0.01 | F37: 25992 | L37: 104
B38: Beachcomb | C38: Jefferson | D38: 8 miles SW of Wartm Springs, OR | E38: 0 | F38: 13648 | M38: 44
B39: Bench | C39: Jefferson | D39: 9 miles West of Metolius, OR | E39: 0 | F39: 20180 | I39: 609 | J39: 327 | K39: 120 | L39: 18
B40: Big Grass | C40: Malheur | D40: 21 miles SE of Rome, OR | E40: 0.05 | F40: 280000 | L40: 336
B41: Bob Creek | C41: Baker | D41: 2 miles NW of Oxbow, OR | E41: 0 | F41: 600 | L41: 3
B42: Bologna | C42: Grant | D42: 4 miles NE of Kimberly, OR | E42: 0.44 | F42: 2425 | L42: 5 | O42: 1
B43: Brewer | C43: Jefferson | D43: 12 miles SE of Madras, OR | E43: 0.05 | F43: 51308 | I43: 126 | J43: 335 | K43: 75 | L43: 1784 | Q43: 15
B44: Burnt Creek | C44: Jefferson | D44: 9 miles Se of Lakeview, OR | E44: 0 | F44: 3015 | I44: 18 | L44: 46
B45: Castle | C45: Douglas | D45: (blank) | E45: 0 | F45: 1400
...

Sheet ODF data
A1: 1 | B1: 2 | C1: 3 | D1: 4 | E1: 5 | F1: 6 | G1: 7 | H1: 8 | I1: 9
A2: Year | B2: Agency | C2: ODF report effective date | D2: ODF Active fires | E2: ODF total fires YTD | F2: ODF acres YTD | G2: Statewide active fires | H2: Statewide total fires YTD | I2: Statewide acres burned YTD | J2: Aver. fire size (acres) | K2: Note/source (ODF data)
A3: 2020 | B3: ODF | C3: 44123 | D3: 0 | E3: 912 | F3: 551816 | G3: 0 | H3: 2027 | I3: 1221324 | J3: =I3/H3 -> 602.52787 | K3: https://web.archive.org/web/20201025013059/https://odfwildfire.wpengine.com/2020/10/19/final-odf-fire-report-for-2020-fire-season/
A4: 2021 | B4: ODF | C4: 44492 | D4: 0 | G4: 0 | H4: 1858 | I4: 827596 | J4: =I4/H4 -> 445.42304 | K4: https://www.statesmanjournal.com/story/news/2020/10/30/climate-change-oregon-wildfires-2020/6056170002/
A5: 2022 | B5: ODF | C5: 44860 | D5: 0 | E5: 967 | F5: 16975 | G5: 0 | H5: 1784 | I5: 344899 | J5: =I5/H5 -> 193.32904
A6: 2023 | B6: ODF | C6: 45217 | D6: 0 | E6: 975 | F6: 17968 | G6: 0 | H6: 1731 | I6: 190507 | J6: =I6/H6 -> 110.05604 | K6: https://www.tillamookheadlightherald.com/news/widespread-rain-prompts-the-end-of-the-2022-fire-season/article_bfb16888-554f-11ed-89b9-b721df9c368e.html
A7: 2024 | B7: ODF | C7: 45558 | D7: 0 | E7: 848 | F7: 321600 | G7: 0 | H7: 2039 | I7: 1915554 | J7: =I7/H7 -> 939.45758 | K7: https://odffire.com/
A8: 2025 | B8: ODF | C8: 45947 | D8: 0 | E8: 1091 | F8: 23796 | G8: 3 | H8: 2944 | I8: 340991 | J8: =I8/H8 -> 115.82575 | K8: https://odffire.com/ | M8: Note: site indicated 3466 (9/15) has to be a typo. Probably 2466
A9: 2026 | B9: ODF | C9: 46227 | D9: 16 | E9: 616 | F9: 81098 | G9: 30 | H9: 1238 | I9: 577106 | J9: =I9/H9 -> 466.15994
O10: Statewide total acres burned and total number of wildfires
O11: 2020-2026 (
O12: =CONCATENATE(O11,"as of: ",P14,")",O13) -> 2020-2026 (as of: 07/24/2026) source: ODF Wildland Fire statistics
O13: source: ODF Wildland Fire statistics
O14: =C9 -> 46227 | P14: =TEXT(O14,"MM/DD/YyyY") -> 07/24/2026
O15: =CONCATENATE(O10," ",O12," ",O13) -> Statewide total acres burned and total number of wildfires 2020-2026 (as of: 07/24/2026) source: ODF Wildland Fire statistics source: ODF Wildland Fire statistics

Sheet Rpt-Status, name, county
A1: =E3 -> 45824 | B1: Daily Wildfire Report
A2: =B19 -> 2026 | B2: Wildfire Report - by Fire Status, Name | D2: State of Oregon Fires and Hotspots Dashboard
D3: ODEM wildfire data as of | E3: 45824
A4: Note: Acres burned value in daily report is based on fires started within 100 days, consequently the total adjusts over time as older fires are removed, and new fires are reported. A Large Fire as defined by the National Wildland Coordinating Group is any wildland fire in timber 100 acres or greater, and 300 acres or greater in grasslands/rangelands, or has an Incident Management Team assigned to it. | D4: All active fires | E4: =_xlfn.IFNA(VLOOKUP($E$3,ODEM,2,FALSE),"no data") -> 9
D5: Acres Burned (in last 100 days) | E5: =_xlfn.IFNA(VLOOKUP($E$3,ODEM,3,FALSE),"no data") -> 15630
D6: Active LARGE fires | E6: =IFERROR(GETPIVOTDATA("Name",$A$10,"Status","Large"),0) -> 37
A9: Number of Tracked Fires by Current Status | D9: ODF Wildland Fire Situation Report | E9: updated as of | F9: =_xlfn.IFNA(VLOOKUP($B$19,ODF,3,FALSE),"no data") -> 46227 | H9: OEM Evacuation Information (addresses)
B10: # of Fires | E10: ODF Land | F10: Statewide | H10: Be Ready | I10: Be Set | J10: Go NOW | N10: R | O10: C | P10: O
A11: Large | B11: 37 | D11: Active large fires | E11: =_xlfn.IFNA(VLOOKUP($B$19,ODF,4,FALSE),"no data") -> 16 | F11: =_xlfn.IFNA(VLOOKUP($B$19,ODF,7,FALSE),"no data") -> 30 | H11: 7816 | I11: 4000 | J11: 2831 | N11: 26 | P11: 72
A12: Cont | B12: 23 | D12: Total fires YTD | E12: =_xlfn.IFNA(VLOOKUP($B$19,ODF,5,FALSE),"no data") -> 616 | F12: =_xlfn.IFNA(VLOOKUP($B$19,ODF,8,FALSE),"no data") -> 1238 | H12: Evacuation | N12: Structure loss
A13: PL | B13: 1 | D13: Acres burned YTD | E13: =_xlfn.IFNA(VLOOKUP($B$19,ODF,6,FALSE),"no data") -> 81098 | F13: =_xlfn.IFNA(VLOOKUP($B$19,ODF,9,FALSE),"no data") -> 577106
A14: Grand Total | B14: 61
B15: Legend
B16: Large=Active large fire
B17: Cont=Fire contained
B18: PL=Contained with property loss
A19: Year | B19: 2026
A20: Northwest Large Fire Information Summary | I20: Evacuation | L20: Threatened | O20: Destroyed
F21: VALUES
A22: Status | B22: Name | C22: County | D22: Location | E22: Containment | F22: Acres burned | G22: Injuries. | H22: Fatalities. | I22: Lev1 | J22: Lev2 | K22: Lev3 | L22: Residential | M22: Commercial | N22: Other | O22: Residential_ | P22: Commercial_ | Q22: Other_
A23: Large | B23: 0494 Akawa Butte | C23: Jefferson | D23: 12 miles NW of Terrebone, OR | E23: 0.05 | F23: 27222 | I23: 3898 | J23: 396 | K23: 460 | L23: 4812 | O23: 2
B24: 0497 Henry | C24: Crook | D24: 5 miles S of Paulina Guard Station, OR | E24: 0.35 | F24: 28827 | L24: 8
B25: 0500 Coyote | C25: Crook | D25: 5 mile E of Coyote Butte, OR | E25: 0.57 | F25: 17447 | L25: 100
B26: 0579 Ten Mile | C26: Jefferson | D26: 2 miles NE of Gateway, OR | E26: 0.77 | F26: 4834 | L26: 30
B27: 0586 | C27: Wasco | D27: 6 miles NE of Gateway, OR | E27: 0 | F27: 191 | I27: 308 | J27: 1068 | K27: 61
B28: 0587 Shingle | C28: Wheeler | D28: 14 miles SE of Mitchell, OR | E28: 0 | F28: 53976 | I28: 0 | J28: 5 | K28: 17 | O28: 3
B29: 0611 | C29: Crook | D29: 12 miles NE of Prineville, OR | E29: 0 | F29: 2136
B30: 2680 Diamond Craters | C30: Harney | D30: 9 miles NW of Diamond, OR | E30: 0.8 | F30: 745 | L30: 15
B31: 8 Mile | C31: Wasco | D31: 8 miles W of Dufur, OR | E31: 0 | F31: 532
B32: Anthony | C32: Baker | D32: 5 miles W of Hutchinson, OR | E32: 0.89 | F32: 2550 | I32: 24 | J32: 12 | L32: 50
B33: Bald Mountain | C33: Harney | D33: 10 miles W of Diamond, OR | E33: 0.01 | F33: 25992 | L33: 104
B34: Beachcomb | C34: Jefferson | D34: 8 miles SW of Wartm Springs, OR | E34: 0 | F34: 13648 | M34: 44
B35: Bench | C35: Jefferson | D35: 9 miles West of Metolius, OR | E35: 0 | F35: 20180 | I35: 609 | J35: 327 | K35: 120 | L35: 18
B36: Big Grass | C36: Malheur | D36: 21 miles SE of Rome, OR | E36: 0.05 | F36: 280000 | L36: 336
B37: Bob Creek | C37: Baker | D37: 2 miles NW of Oxbow, OR | E37: 0 | F37: 600 | L37: 3
B38: Bologna | C38: Grant | D38: 4 miles NE of Kimberly, OR | E38: 0.44 | F38: 2425 | L38: 5 | O38: 1
B39: Brewer | C39: Jefferson | D39: 12 miles SE of Madras, OR | E39: 0.05 | F39: 51308 | I39: 126 | J39: 335 | K39: 75 | L39: 1784 | Q39: 15
B40: Burnt Creek | C40: Jefferson | D40: 9 miles Se of Lakeview, OR | E40: 0 | F40: 3015 | I40: 18 | L40: 46
B41: Castle | C41: Douglas | D41: (blank) | E41: 0 | F41: 1400
B42: Colman Creek | C42: Harney | D42: 11 miles NW of Dunnean, OR | E42: 0 | F42: 130000
...

Sheet EVENTS
A1: Wildfire Response Summary
A2: Year | B2: Date | C2: Fire | D2: Location | E2: Event Type | F2: Outreach Response | G2: Homes Destroyed | H2: Structures threatened | I2: Highest evac level | J2: Large pop. Impact | K2: Fire trend UP? | L2: AQI unhealthy or worse | M2: Multi Agency Response | N2: Notes | O2: Details
A3: 2024 | B3: 45486 | C3: Larch Creek | D3: Maupin | E3: Community / Informational Meeting | F3: Attended in person | I3: x | J3: x | K3: x
A4: 2024 | B4: 45490 | C4: Cow Valley | D4: Vale | E4: Community / Informational Meeting | F4: Attended in person | I4: x | K4: x
A5: 2024 | B5: 45493 | C5: Lone Rock | D5: John Day | E5: Community / Informational Meeting | F5: Attended in person | J5: x | K5: x | L5: x
A6: 2024 | B6: 45495 | C6: Red | D6: Crescent Lake | E6: Community / Informational Meeting | F6: Attended in person
A7: 2024 | B7: 45496 | C7: Ore | D7: Vida | E7: Community / Informational Meeting | F7: Attended in person
A8: 2024 | B8: 45497 | C8: Falls | D8: Burns | E8: Community / Informational Meeting | F8: Traveled / did not participate | G8: x | I8: x | J8: x | K8: x | N8: Traveled to attend, mis-communication on date (7/23)
A9: 2024 | B9: 45498 | C9: Lone Rock | D9: John Day | E9: MARC | F9: Traveled / did not participate | G9: x | I9: x | J9: x | K9: x | L9: x | N9: Traveled to attend, received cancel notice next morning
A10: 2024 | B10: 45502 | N10: Leadership meeting to discuss response strategy going foreward
A11: 2024 | B11: 45504 | C11: Pyramid | E11: Community / Informational Meeting | F11: Did not attend | N11: Minimal evacuations
A12: 2024 | B12: 45506 | C12: Adam Mountain | E12: Community / Informational Meeting | F12: Did not attend | N12: No evacuations scheduled
A13: 2024 | B13: 45507 | C13: Whisky Creek | E13: Community / Informational Meeting | F13: Did not attend | I13: x | N13: Short notice
A14: 2024 | B14: 45509 | C14: Battle Mtn Complex | E14: Community / Informational Meeting | F14: Did not attend | I14: x | N14: Short notice
A15: 2024 | B15: 45510 | C15: Falls | D15: Burns | E15: Community / Informational Meeting | F15: Attended in person | G15: x | I15: x | J15: x | K15: x | L15: x | N15: 13 homes destroyed
A16: 2024 | B16: 45511 | C16: Elk Lane | D16: Virtual | E16: VIRTUAL - Informational Meeting | F16: Attended virtual event | I16: x | J16: x | K16: x | N16: 206 addresses in level 3 (as of 8/7)
A17: 2024 | B17: 45512 | C17: Town Gulch | E17: Community / Informational Meeting | F17: Did not attend | G17: x | I17: x | J17: x | K17: x | L17: x | N17: Short notice. Same day. 6+ hr. plus travel.
A18: 2024 | B18: 45512 | C18: Willamette Complex | E18: Community / Informational Meeting | F18: Did not attend | I18: x | N18: Remote region, limited impact with 6 addresses in evac status (L3)
A19: 2024 | B19: 45513 | C19: Lane 1 | E19: Community / Informational Meeting | F19: Did not attend | K19: x | N19: no homes destroyed, level 1 evacuations
A20: 2024 | B20: 45515 | C20: Town Gulch | E20: Community / Informational Meeting | F20: Did not attend | G20: x | I20: x | K20: x | N20: Short notice. Posted Saturday night at 10:15pm on Facebook, found on Monday
A21: 2024 | B21: 45517 | C21: Falls | D21: Burns | E21: Fire resource meeting | F21: Attended in person | G21: x | I21: x | J21: x | K21: x | L21: x | M21: x | N21: Invited by Katie Wollstein, OSU
A22: 2024 | B22: 45520 | C22: Willamette Complex | E22: Community / Informational Meeting | F22: Did not attend | K22: x | N22: Level 1 evac only. No structures damaged | O22: August 16th at 6:30 pm at the Banner Bank Amphitheater in Greenwaters Park in Oakridge, OR.
A23: 2024 | B23: 45526 | C23: Battle Mtn Complex | D23: Monument | E23: Fire resource meeting | F23: Attended in person | G23: x | J23: x | M23: x | N23: Resource meeting planned. Invited to attend. Adding to itinerary on return leg of existing outreach trip (La Grande firewise panel) | O23: 11-1pm at Monument Senior Center
A24: 2024 | B24: 45538 | C24: Battle Mtn Complex | D24: Pilot Rock | E24: Fire resource meeting | F24: Attended in person | G24: x | J24: x | M24: x | N24: Resource meeting planned. DFR "welcome to attend". Sponsored by Cattlemen's association | O24: Sept. 3, 3:00-5:00pm at Pilot Rock City Hall
A25: 2024 | B25: 45546 | C25: Bachelor Complex | D25: Sun River | E25: Community / Informational Meeting | F25: Did not attend | I25: x | J25: x | L25: x | N25: 6pm - Three Rivers Elementary Schol | O25: Three Rivers School | 56900 Enterprise Drive, Sunriver, OR 97707
A26: 2024 | B26: 45548 | C26: Rail Ridge | D26: Seneca | E26: Community / Informational Meeting | F26: Did not attend | G26: x | I26: x | J26: x | K26: x | L26: x | N26: Short notice of meeting - found on Facebook | O26: 5 p.m. today at the Izee schoolhouse, 45477 Izee-Paulina Lane Seneca, OR
A27: 2024 | B27: 45552 | C27: Durkee | D27: Durkee | E27: Fire resource meeting | F27: Attended in person | G27: x | M27: x | N27: Meeting in Durkee 6-8pm | O27: 28716 Old Highway 30 (28716 Old Highway 30, Durkee, Oregon 97905
A28: 2024 | B28: 45553 | C28: Cow Valley | D28: Vale | E28: Fire resource meeting | F28: Attended in person | G28: x | M28: x | N28: Meeting in Vale 7-9pm
A29: 2024 | B29: 45554 | C29: Town Gulch | D29: Richland | E29: Fire resource meeting | F29: Attended in person | G29: x | M29: x | N29: Meeting in Richland 6-8pm | O29: 42008 Moody Rd (42008 Moody Rd, Richland, Oregon 97870)
A30: 2025 | B30: 45821 | C30: Rowena | D30: The Dalles | E30: Community Meeting | F30: Did not attend | G30: x | I30: 2 | J30: x | K30: x | N30: Incident team and other agencies to proviede update and resources | O30: 7pm, The Dalles High school
A31: 2025 | B31: 45824 | C31: Rowena | D31: The Dalles | E31: MARC | F31: Attended in person | G31: x | I31: 2 | J31: x | K31: x | M31: x | N31: First MARC of multiple expected events (Monday 3-6pm) | O31: 401 E. 3rd St. Ste 100 The Dalles, OR Veteran Services Office
A32: 2025 | B32: 45826 | C32: Rowena | D32: The Dalles | E32: MARC | F32: Attended in person | G32: 56 | H32: 136 | I32: 2 | J32: x | K32: x | M32: x | N32: Second MARC of multiple expected events (Wednesday 4-7pm) | O32: 401 E. 3rd St. Ste 100 The Dalles, OR Veteran Services Office
A33: 2025 | B33: 45851 | C33: Highland | D33: Prineville | E33: Community / Informational Meeting | F33: Attended virtually | G33: 0 | I33: 3 | J33: x | K33: x | N33: Community meeting for fire information. Streamed on Facebook | O33: 6-6:30pm, via Facebook video
A34: 2025 | B34: 45854 | C34: Rowena | D34: The Dalles | E34: MARC - focussed event | F34: Not included (focussed event) | G34: 56 | J34: x | N34: MARC focussed on Mass Care resources | O34: 5pm, 7/16 at Gloris Center in The Dalles
A35: 2026 | B35: 46216 | C35: Salmon | D35: Prairie City | E35: Community Meeting | F35: Did not attend | G35: 0 | H35: x | I35: 3 | J35: x | K35: x | N35: Streamed on Salmon Fire OR 2026 facebook page | O35: 6pm, Prairie City High School
A36: 2026 | B36: 46217 | C36: Anthony | D36: Baker City | E36: Community Meeting | F36: Did not attend | G36: 0 | H36: x | I36: 2 | K36: x | O36: 7:00pm, Churchill School
A37: 2026 | B37: 46218 | C37: Evans Creek Rd | D37: East Evans Creek | E37: Community Meeting | F37: Did not attend | G37: 0 | H37: x | I37: 3 | J37: x | K37: x | L37: x | N37: Will be live streamed on Facebook: facebook.com/odfsouthwest | O37: 6:30pm, Shady Cove school gym

Sheet Rpt-County, status, name
A2: ='Rpt-Status, name, county'!B19 -> 2026 | B2: Wildfire Report - by County, Status, Name | G2: Evacuation | J2: Threatened | M2: Destroyed
F3: VALUES
A4: County | B4: Status | C4: Name | D4: Location | E4: Containment | F4: Acres | G4: Lev1 | H4: Lev2 | I4: Lev3 | J4: Res-Thr | K4: Comm-Thr | L4: Other-Thr | M4: Res-DSTY | N4: Comm-DSTY | O4: Other-DSTY
A5: Malheur | B5: Large | C5: Big Grass | D5: 21 miles SE of Rome, OR | E5: 0.05 | F5: 280000 | J5: 336 | S5: State | T5: County | V5: Homes destroyed
C6: Hat | D6: 9 miles SE of Venator, OR | E6: 0.35 | F6: 42000 | J6: 32 | S6: Oregon | T6: Baker | U6: =CONCATENATE(T6," Total") -> Baker Total | V6: =IFERROR(VLOOKUP(U6,$A$5:$O$300,13,FALSE),0) -> 0
B7: Large Total | F7: 322000 | J7: 368 | S7: Oregon | T7: Benton | U7: =CONCATENATE(T7," Total") -> Benton Total | V7: =IFERROR(VLOOKUP(U7,$A$5:$O$300,13,FALSE),0) -> 0
B8: Cont | C8: Airport | D8: 3 mile E of Danner, OR | E8: 1 | F8: 0 | G8: 0 | S8: Oregon | T8: Clackamas | U8: =CONCATENATE(T8," Total") -> Clackamas Total | V8: =IFERROR(VLOOKUP(U8,$A$5:$O$300,13,FALSE),0) -> 0
C9: Butterfield Spring | D9: 7 miles NW of Ontario, OR | E9: 1 | F9: 2750 | S9: Oregon | T9: Clatsop | U9: =CONCATENATE(T9," Total") -> Clatsop Total | V9: =IFERROR(VLOOKUP(U9,$A$5:$O$300,13,FALSE),0) -> 0
C10: Cow Camp Complex | D10: 9 miles SW of Eagle, OR | E10: 1 | F10: 8044 | S10: Oregon | T10: Columbia | U10: =CONCATENATE(T10," Total") -> Columbia Total | V10: =IFERROR(VLOOKUP(U10,$A$5:$O$300,13,FALSE),0) -> 0
C11: Crowley | D11: 4 miles E of Crowley, OR | E11: 10 | F11: 1500 | S11: Oregon | T11: Coos | U11: =CONCATENATE(T11," Total") -> Coos Total | V11: =IFERROR(VLOOKUP(U11,$A$5:$O$300,13,FALSE),0) -> 0
C12: Lytle | D12: 3 miles S of Vale, OR | E12: 1 | F12: 6052 | G12: 0 | S12: Oregon | T12: Crook | U12: =CONCATENATE(T12," Total") -> Crook Total | V12: =IFERROR(VLOOKUP(U12,$A$5:$O$300,13,FALSE),0) -> 0
C13: Whiskey | D13: 20 miles SE of Crane, OR | E13: 1 | F13: 999 | S13: Oregon | T13: Curry | U13: =CONCATENATE(T13," Total") -> Curry Total | V13: =IFERROR(VLOOKUP(U13,$A$5:$O$300,13,FALSE),0) -> 0
B14: Cont Total | F14: 19345 | G14: 0 | S14: Oregon | T14: Deschutes | U14: =CONCATENATE(T14," Total") -> Deschutes Total | V14: =IFERROR(VLOOKUP(U14,$A$5:$O$300,13,FALSE),0) -> 0
A15: Malheur Total | F15: 341345 | G15: 0 | J15: 368 | S15: Oregon | T15: Douglas | U15: =CONCATENATE(T15," Total") -> Douglas Total | V15: =IFERROR(VLOOKUP(U15,$A$5:$O$300,13,FALSE),0) -> 0
A16: Harney | B16: Large | C16: 2680 Diamond Craters | D16: 9 miles NW of Diamond, OR | E16: 0.8 | F16: 745 | J16: 15 | S16: Oregon | T16: Gilliam | U16: =CONCATENATE(T16," Total") -> Gilliam Total | V16: =IFERROR(VLOOKUP(U16,$A$5:$O$300,13,FALSE),0) -> 13
C17: Bald Mountain | D17: 10 miles W of Diamond, OR | E17: 0.01 | F17: 25992 | J17: 104 | S17: Oregon | T17: Grant | U17: =CONCATENATE(T17," Total") -> Grant Total | V17: =IFERROR(VLOOKUP(U17,$A$5:$O$300,13,FALSE),0) -> 1
C18: Colman Creek | D18: 11 miles NW of Dunnean, OR | E18: 0 | F18: 130000 | S18: Oregon | T18: Harney | U18: =CONCATENATE(T18," Total") -> Harney Total | V18: =IFERROR(VLOOKUP(U18,$A$5:$O$300,13,FALSE),0) -> 0
C19: Egypt | D19: 13 miles N of Riley, OR | E19: 0.8 | F19: 4553 | S19: Oregon | T19: Hood River | U19: =CONCATENATE(T19," Total") -> Hood River Total | V19: =IFERROR(VLOOKUP(U19,$A$5:$O$300,13,FALSE),0) -> 0
C20: Jackass Butte | D20: 15 miles W of Diamond, OR | E20: 0.3 | F20: 18539 | J20: 34 | O20: 2 | S20: Oregon | T20: Jackson | U20: =CONCATENATE(T20," Total") -> Jackson Total | V20: =IFERROR(VLOOKUP(U20,$A$5:$O$300,13,FALSE),0) -> 1
C21: Second Flat | D21: 6 miles NE of Riley, OR | E21: 0.05 | F21: 76958 | J21: 1721 | O21: 2 | S21: Oregon | T21: Jefferson | U21: =CONCATENATE(T21," Total") -> Jefferson Total | V21: =IFERROR(VLOOKUP(U21,$A$5:$O$300,13,FALSE),0) -> 2
C22: Stubble | D22: 17 miles NW of Diamond, OR | E22: 0.8 | F22: 15673 | J22: 76 | S22: Oregon | T22: Josephine | U22: =CONCATENATE(T22," Total") -> Josephine Total | V22: =IFERROR(VLOOKUP(U22,$A$5:$O$300,13,FALSE),0) -> 0
B23: Large Total | F23: 272460 | J23: 1950 | O23: 4 | S23: Oregon | T23: Klamath | U23: =CONCATENATE(T23," Total") -> Klamath Total | V23: =IFERROR(VLOOKUP(U23,$A$5:$O$300,13,FALSE),0) -> 0
B24: Cont | C24: Hoop | D24: 75 miles S of Burns, OR | E24: 1 | F24: 960 | S24: Oregon | T24: Lake | U24: =CONCATENATE(T24," Total") -> Lake Total | V24: =IFERROR(VLOOKUP(U24,$A$5:$O$300,13,FALSE),0) -> 0
B25: Cont Total | F25: 960 | S25: Oregon | T25: Lane | U25: =CONCATENATE(T25," Total") -> Lane Total | V25: =IFERROR(VLOOKUP(U25,$A$5:$O$300,13,FALSE),0) -> 0
A26: Harney Total | F26: 273420 | J26: 1950 | O26: 4 | S26: Oregon | T26: Lincoln | U26: =CONCATENATE(T26," Total") -> Lincoln Total | V26: =IFERROR(VLOOKUP(U26,$A$5:$O$300,13,FALSE),0) -> 0
A27: Wheeler | B27: Large | C27: 0587 Shingle | D27: 14 miles SE of Mitchell, OR | E27: 0 | F27: 53976 | G27: 0 | H27: 5 | I27: 17 | M27: 3 | S27: Oregon | T27: Linn | U27: =CONCATENATE(T27," Total") -> Linn Total | V27: =IFERROR(VLOOKUP(U27,$A$5:$O$300,13,FALSE),0) -> 0
C28: Rowe Creek Complex | D28: 13 miles S of Fossil | E28: 0.31 | F28: 208759 | G28: 4 | H28: 0 | I28: 9 | S28: Oregon | T28: Malheur | U28: =CONCATENATE(T28," Total") -> Malheur Total | V28: =IFERROR(VLOOKUP(U28,$A$5:$O$300,13,FALSE),0) -> 0
B29: Large Total | F29: 262735 | G29: 4 | H29: 5 | I29: 26 | M29: 3 | S29: Oregon | T29: Marion | U29: =CONCATENATE(T29," Total") -> Marion Total | V29: =IFERROR(VLOOKUP(U29,$A$5:$O$300,13,FALSE),0) -> 0
A30: Wheeler Total | F30: 262735 | G30: 4 | H30: 5 | I30: 26 | M30: 3 | S30: Oregon | T30: Morrow | U30: =CONCATENATE(T30," Total") -> Morrow Total | V30: =IFERROR(VLOOKUP(U30,$A$5:$O$300,13,FALSE),0) -> 0
A31: Gilliam | B31: Large | C31: Hay Creek Complex | D31: 9 miles SE of Eagle, OR | E31: 0.6 | F31: 181821 | G31: 217 | H31: 95 | I31: 0 | M31: 13 | O31: 5 | S31: Oregon | T31: Multnomah | U31: =CONCATENATE(T31," Total") -> Multnomah Total | V31: =IFERROR(VLOOKUP(U31,$A$5:$O$300,13,FALSE),0) -> 0
B32: Large Total | F32: 181821 | G32: 217 | H32: 95 | I32: 0 | M32: 13 | O32: 5 | S32: Oregon | T32: Polk | U32: =CONCATENATE(T32," Total") -> Polk Total | V32: =IFERROR(VLOOKUP(U32,$A$5:$O$300,13,FALSE),0) -> 0
B33: Cont | C33: 0246 Rhea | D33: Gilliam County | E33: 1 | F33: 450 | S33: Oregon | T33: Sherman | U33: =CONCATENATE(T33," Total") -> Sherman Total | V33: =IFERROR(VLOOKUP(U33,$A$5:$O$300,13,FALSE),0) -> 0 | X33: =A2 -> 2026 | Y33: Wildfire damage by County
C34: 0366 Cedar | D34: 7 miles S of Arlington, OR | E34: 1 | F34: 440 | S34: Oregon | T34: Tillamook | U34: =CONCATENATE(T34," Total") -> Tillamook Total | V34: =IFERROR(VLOOKUP(U34,$A$5:$O$300,13,FALSE),0) -> 0 | X34: =CONCATENATE(X33,Y33," ",X38) -> 2026 Wildfire damage by County Homes destroyed: 26
C35: 518 Sully | D35: 9 miles E of Arlington, OR | E35: 10 | F35: 640 | G35: 15 | S35: Oregon | T35: Umatilla | U35: =CONCATENATE(T35," Total") -> Umatilla Total | V35: =IFERROR(VLOOKUP(U35,$A$5:$O$300,13,FALSE),0) -> 6
B36: Cont Total | F36: 1530 | G36: 15 | S36: Oregon | T36: Union | U36: =CONCATENATE(T36," Total") -> Union Total | V36: =IFERROR(VLOOKUP(U36,$A$5:$O$300,13,FALSE),0) -> 0
A37: Gilliam Total | F37: 183351 | G37: 232 | H37: 95 | I37: 0 | M37: 13 | O37: 5 | S37: Oregon | T37: Wallowa | U37: =CONCATENATE(T37," Total") -> Wallowa Total | V37: =IFERROR(VLOOKUP(U37,$A$5:$O$300,13,FALSE),0) -> 0 | X37: =V43 -> 26 | Y37: Homes destroyed:
A38: Jefferson | B38: Large | C38: 0494 Akawa Butte | D38: 12 miles NW of Terrebone, OR | E38: 0.05 | F38: 27222 | G38: 3898 | H38: 396 | I38: 460 | J38: 4812 | M38: 2 | S38: Oregon | T38: Wasco | U38: =CONCATENATE(T38," Total") -> Wasco Total | V38: =IFERROR(VLOOKUP(U38,$A$5:$O$300,13,FALSE),0) -> 0 | X38: =CONCATENATE(Y37,X37) -> Homes destroyed: 26
C39: 0579 Ten Mile | D39: 2 miles NE of Gateway, OR | E39: 0.77 | F39: 4834 | J39: 30 | S39: Oregon | T39: Washington | U39: =CONCATENATE(T39," Total") -> Washington Total | V39: =IFERROR(VLOOKUP(U39,$A$5:$O$300,13,FALSE),0) -> 0
C40: Beachcomb | D40: 8 miles SW of Wartm Springs, OR | E40: 0 | F40: 13648 | K40: 44 | S40: Oregon | T40: Wheeler | U40: =CONCATENATE(T40," Total") -> Wheeler Total | V40: =IFERROR(VLOOKUP(U40,$A$5:$O$300,13,FALSE),0) -> 3
C41: Bench | D41: 9 miles West of Metolius, OR | E41: 0 | F41: 20180 | G41: 609 | H41: 327 | I41: 120 | J41: 18 | S41: Oregon | T41: Yamhill | U41: =CONCATENATE(T41," Total") -> Yamhill Total | V41: =IFERROR(VLOOKUP(U41,$A$5:$O$300,13,FALSE),0) -> 0
...

Sheet County chart
A1: Status | B1: (Multiple Items)
A2: ='Rpt-Status, name, county'!B19 -> 2026 | B2: Wildfire Report - by County, Acres, Loss
C3: VALUES | AF3: =CONCATENATE(AF4,AG4) -> 2026 Wildfire impact by County - Acres burned (large fires), Structures destroyed
A4: County | B4: Containment | C4: Acres | D4: Resid. | E4: Comm. | F4: Minor | G4: RV/home | AF4: =$A$2 -> 2026 | AG4: Wildfire impact by County - Acres burned (large fires), Structures destroyed
A5: Malheur | C5: 341345 | AG5: Acres burned and Stuctures destroyed
A6: Harney | C6: 273420 | F6: 4
A7: Wheeler | C7: 262735 | D7: 3
A8: Gilliam | C8: 183351 | D8: 13 | F8: 5
A9: Jefferson | C9: 120207 | D9: 2 | F9: 15
A10: Crook | C10: 48760
A11: Umatilla | C11: 39957 | D11: 6 | F11: 40
A12: Grant | C12: 33350 | D12: 1 | F12: 2
A13: Baker | C13: 26114
A14: Douglas | C14: 16400
A15: Jackson | C15: 15639 | D15: 1 | F15: 6
A16: Wasco | C16: 3704
A17: Deschutes | C17: 2621
A18: Wallowa | C18: 740
A19: Klamath | C19: 247
A20: Grand Total | C20: 1368590 | D20: 26 | F20: 72
A45: State | B45: County | C45: Acres burned | D45: Res-DSTY | E45: Comm-DSTY | F45: Other-DSTY | G45: RV/Home | AF45: =CONCATENATE(AF46,AG46," ",AG47) -> 2026 Wildfire impact by County - Acres burned (large fires) Approximate total acres burned (large fires): 1.369 M
A46: Oregon | B46: Baker | C46: =IFERROR(VLOOKUP(B46,$A$5:$C$41,3,FALSE),0) -> 26114 | D46: =IFERROR(VLOOKUP($B46,$A$5:$G$41,4,FALSE),0) -> 0 | E46: =IFERROR(VLOOKUP($B46,$A$5:$G$41,5,FALSE),0) -> 0 | F46: =IFERROR(VLOOKUP($B46,$A$5:$G$41,6,FALSE),0) -> 0 | G46: =IFERROR(VLOOKUP($B46,$A$5:$G$41,7,FALSE),0) -> 0 | AF46: =$A$2 -> 2026 | AG46: Wildfire impact by County - Acres burned (large fires)
A47: Oregon | B47: Benton | C47: =IFERROR(VLOOKUP(B47,$A$5:$C$41,3,FALSE),0) -> 0 | D47: =IFERROR(VLOOKUP($B47,$A$5:$G$41,4,FALSE),0) -> 0 | E47: =IFERROR(VLOOKUP($B47,$A$5:$G$41,5,FALSE),0) -> 0 | F47: =IFERROR(VLOOKUP($B47,$A$5:$G$41,6,FALSE),0) -> 0 | G47: =IFERROR(VLOOKUP($B47,$A$5:$G$41,7,FALSE),0) -> 0 | AG47: =D90 -> Approximate total acres burned (large fires): 1.369 M
A48: Oregon | B48: Clackamas | C48: =IFERROR(VLOOKUP(B48,$A$5:$C$41,3,FALSE),0) -> 0 | D48: =IFERROR(VLOOKUP($B48,$A$5:$G$41,4,FALSE),0) -> 0 | E48: =IFERROR(VLOOKUP($B48,$A$5:$G$41,5,FALSE),0) -> 0 | F48: =IFERROR(VLOOKUP($B48,$A$5:$G$41,6,FALSE),0) -> 0 | G48: =IFERROR(VLOOKUP($B48,$A$5:$G$41,7,FALSE),0) -> 0
A49: Oregon | B49: Clatsop | C49: =IFERROR(VLOOKUP(B49,$A$5:$C$41,3,FALSE),0) -> 0 | D49: =IFERROR(VLOOKUP($B49,$A$5:$G$41,4,FALSE),0) -> 0 | E49: =IFERROR(VLOOKUP($B49,$A$5:$G$41,5,FALSE),0) -> 0 | F49: =IFERROR(VLOOKUP($B49,$A$5:$G$41,6,FALSE),0) -> 0 | G49: =IFERROR(VLOOKUP($B49,$A$5:$G$41,7,FALSE),0) -> 0
A50: Oregon | B50: Columbia | C50: =IFERROR(VLOOKUP(B50,$A$5:$C$41,3,FALSE),0) -> 0 | D50: =IFERROR(VLOOKUP($B50,$A$5:$G$41,4,FALSE),0) -> 0 | E50: =IFERROR(VLOOKUP($B50,$A$5:$G$41,5,FALSE),0) -> 0 | F50: =IFERROR(VLOOKUP($B50,$A$5:$G$41,6,FALSE),0) -> 0 | G50: =IFERROR(VLOOKUP($B50,$A$5:$G$41,7,FALSE),0) -> 0
A51: Oregon | B51: Coos | C51: =IFERROR(VLOOKUP(B51,$A$5:$C$41,3,FALSE),0) -> 0 | D51: =IFERROR(VLOOKUP($B51,$A$5:$G$41,4,FALSE),0) -> 0 | E51: =IFERROR(VLOOKUP($B51,$A$5:$G$41,5,FALSE),0) -> 0 | F51: =IFERROR(VLOOKUP($B51,$A$5:$G$41,6,FALSE),0) -> 0 | G51: =IFERROR(VLOOKUP($B51,$A$5:$G$41,7,FALSE),0) -> 0
A52: Oregon | B52: Crook | C52: =IFERROR(VLOOKUP(B52,$A$5:$C$41,3,FALSE),0) -> 48760 | D52: =IFERROR(VLOOKUP($B52,$A$5:$G$41,4,FALSE),0) -> 0 | E52: =IFERROR(VLOOKUP($B52,$A$5:$G$41,5,FALSE),0) -> 0 | F52: =IFERROR(VLOOKUP($B52,$A$5:$G$41,6,FALSE),0) -> 0 | G52: =IFERROR(VLOOKUP($B52,$A$5:$G$41,7,FALSE),0) -> 0
A53: Oregon | B53: Curry | C53: =IFERROR(VLOOKUP(B53,$A$5:$C$41,3,FALSE),0) -> 0 | D53: =IFERROR(VLOOKUP($B53,$A$5:$G$41,4,FALSE),0) -> 0 | E53: =IFERROR(VLOOKUP($B53,$A$5:$G$41,5,FALSE),0) -> 0 | F53: =IFERROR(VLOOKUP($B53,$A$5:$G$41,6,FALSE),0) -> 0 | G53: =IFERROR(VLOOKUP($B53,$A$5:$G$41,7,FALSE),0) -> 0
A54: Oregon | B54: Deschutes | C54: =IFERROR(VLOOKUP(B54,$A$5:$C$41,3,FALSE),0) -> 2621 | D54: =IFERROR(VLOOKUP($B54,$A$5:$G$41,4,FALSE),0) -> 0 | E54: =IFERROR(VLOOKUP($B54,$A$5:$G$41,5,FALSE),0) -> 0 | F54: =IFERROR(VLOOKUP($B54,$A$5:$G$41,6,FALSE),0) -> 0 | G54: =IFERROR(VLOOKUP($B54,$A$5:$G$41,7,FALSE),0) -> 0
A55: Oregon | B55: Douglas | C55: =IFERROR(VLOOKUP(B55,$A$5:$C$41,3,FALSE),0) -> 16400 | D55: =IFERROR(VLOOKUP($B55,$A$5:$G$41,4,FALSE),0) -> 0 | E55: =IFERROR(VLOOKUP($B55,$A$5:$G$41,5,FALSE),0) -> 0 | F55: =IFERROR(VLOOKUP($B55,$A$5:$G$41,6,FALSE),0) -> 0 | G55: =IFERROR(VLOOKUP($B55,$A$5:$G$41,7,FALSE),0) -> 0
A56: Oregon | B56: Gilliam | C56: =IFERROR(VLOOKUP(B56,$A$5:$C$41,3,FALSE),0) -> 183351 | D56: =IFERROR(VLOOKUP($B56,$A$5:$G$41,4,FALSE),0) -> 13 | E56: =IFERROR(VLOOKUP($B56,$A$5:$G$41,5,FALSE),0) -> 0 | F56: =IFERROR(VLOOKUP($B56,$A$5:$G$41,6,FALSE),0) -> 5 | G56: =IFERROR(VLOOKUP($B56,$A$5:$G$41,7,FALSE),0) -> 0
A57: Oregon | B57: Grant | C57: =IFERROR(VLOOKUP(B57,$A$5:$C$41,3,FALSE),0) -> 33350 | D57: =IFERROR(VLOOKUP($B57,$A$5:$G$41,4,FALSE),0) -> 1 | E57: =IFERROR(VLOOKUP($B57,$A$5:$G$41,5,FALSE),0) -> 0 | F57: =IFERROR(VLOOKUP($B57,$A$5:$G$41,6,FALSE),0) -> 2 | G57: =IFERROR(VLOOKUP($B57,$A$5:$G$41,7,FALSE),0) -> 0
A58: Oregon | B58: Harney | C58: =IFERROR(VLOOKUP(B58,$A$5:$C$41,3,FALSE),0) -> 273420 | D58: =IFERROR(VLOOKUP($B58,$A$5:$G$41,4,FALSE),0) -> 0 | E58: =IFERROR(VLOOKUP($B58,$A$5:$G$41,5,FALSE),0) -> 0 | F58: =IFERROR(VLOOKUP($B58,$A$5:$G$41,6,FALSE),0) -> 4 | G58: =IFERROR(VLOOKUP($B58,$A$5:$G$41,7,FALSE),0) -> 0
A59: Oregon | B59: Hood River | C59: =IFERROR(VLOOKUP(B59,$A$5:$C$41,3,FALSE),0) -> 0 | D59: =IFERROR(VLOOKUP($B59,$A$5:$G$41,4,FALSE),0) -> 0 | E59: =IFERROR(VLOOKUP($B59,$A$5:$G$41,5,FALSE),0) -> 0 | F59: =IFERROR(VLOOKUP($B59,$A$5:$G$41,6,FALSE),0) -> 0 | G59: =IFERROR(VLOOKUP($B59,$A$5:$G$41,7,FALSE),0) -> 0
... A81: Oregon | B81: Yamhill | C81: =IFERROR(VLOOKUP(B81,$A$5:$C$41,3,FALSE),0) -> 0 | D81: =IFERROR(VLOOKUP($B81,$A$5:$G$41,4,FALSE),0) -> 0 | E81: =IFERROR(VLOOKUP($B81,$A$5:$G$41,5,FALSE),0) -> 0 | F81: =IFERROR(VLOOKUP($B81,$A$5:$G$41,6,FALSE),0) -> 0 | G81: =IFERROR(VLOOKUP($B81,$A$5:$G$41,7,FALSE),0) -> 0
C82: =SUBTOTAL(9,C46:C81) -> 1368590 | D82: =SUBTOTAL(9,D46:D81) -> 26 | E82: =SUBTOTAL(9,E46:E81) -> 0 | F82: =SUBTOTAL(9,F46:F81) -> 72 | G82: =SUBTOTAL(9,G46:G81) -> 0
D86: Round up
B87: Ttl acres | C87: =SUBTOTAL(9,C46:C82) -> 1368590 | D87: =ROUND(C87/1000000,3) -> 1.369 | E87: M
E88: Approximate total acres burned (large fires):
...

Sheet Counties
B1: 2023 Data from US Census
B2: County | C2: Seat | D2: Zip Code | E2: Population | F2: Size
A3: 1 | B3: Baker | C3: Baker City | D3: #VALUE! | E3: 16912 | F3: 3,068 sq mi (7,946 sq km)
A4: 2 | B4: Benton | C4: Corvallis | D4: #VALUE! | E4: 97713 | F4: 676 sq mi (1,751 sq km)
A5: 3 | B5: Clackamas | C5: Oregon City | D5: #VALUE! | E5: 423173 | F5: 1,868 sq mi (4,838 sq km)
A6: 4 | B6: Clatsop | C6: Astoria | D6: #VALUE! | E6: 41102 | F6: 827 sq mi (2,142 sq km)
A7: 5 | B7: Columbia | C7: Saint Helens | D7: #VALUE! | E7: 53880 | F7: 657 sq mi (1,702 sq km)
A8: 6 | B8: Coos | C8: Coquille | D8: #VALUE! | E8: 64212 | F8: 1,600 sq mi (4,144 sq km)
A9: 7 | B9: Crook | C9: Prineville | D9: #VALUE! | E9: 26952 | F9: 2,980 sq mi (7,718 sq km)
A10: 8 | B10: Curry | C10: Gold Beach | D10: #VALUE! | E10: 23296 | F10: 1,627 sq mi (4,214 sq km)
A11: 9 | B11: Deschutes | C11: Bend | D11: #VALUE! | E11: 208513 | F11: 3,018 sq mi (7,817 sq km)
A12: 10 | B12: Douglas | C12: Roseburg | D12: #VALUE! | E12: 112435 | F12: 5,037 sq mi (13,046 sq km)
A13: 11 | B13: Gilliam | C13: Condon | D13: #VALUE! | E13: 2026 | F13: 1,204 sq mi (3,118 sq km)
A14: 12 | B14: Grant | C14: Canyon City | D14: #VALUE! | E14: 7215 | F14: 4,529 sq mi (11,730 sq km)
... A38: 36 | B38: Yamhill | C38: McMinnville | D38: #VALUE! | E38: 108644 | F38: 716 sq mi (1,854 sq km)

Sheet Daily Metrics Log
A1: Date | B1: Active Fires (WF+RX) | C1: Active Large Fires | D1: Total Acres YTD (Large Fires) | E1: Structures Lost | F1: Active Evac-Triggering Fires | G1: Evac Addresses L1 (Be Ready) | H1: Evac Addresses L2 (Be Set) | I1: Evac Addresses L3 (Go NOW) | J1: Note
A2: 46189 | B2: 38 | C2: 0 | D2: 6681 | E2: 0 | F2: 0 | G2: 624 | H2: 0 | I2: 0 | J2: Backfilled from oregon-wildfire-daily-report pipeline archive.
A3: 46190 | B3: 44 | C3: 2 | D3: 7681 | E3: 0 | F3: 1 | G3: 640 | H3: 0 | I3: 0 | J3: Backfilled from oregon-wildfire-daily-report pipeline archive.
A4: 46191 | B4: 48 | C4: 3 | D4: 8881 | E4: 0 | F4: 2 | G4: 19 | H4: 0 | I4: 0 | J4: Backfilled from oregon-wildfire-daily-report pipeline archive.
A5: 46192 | B5: 48 | C5: 3 | D5: 8786 | E5: 0 | F5: 0 | G5: 3 | H5: 0 | I5: 0 | J5: Backfilled from oregon-wildfire-daily-report pipeline archive.
A6: 46193 | B6: 23 | C6: 2 | D6: 8786 | E6: 0 | F6: 0 | G6: 3 | H6: 0 | I6: 0 | J6: Backfilled from oregon-wildfire-daily-report pipeline archive.
A7: 46194 | B7: 23 | C7: 2 | D7: 8786 | E7: 0 | F7: 0 | G7: 3 | H7: 0 | I7: 0 | J7: Backfilled from oregon-wildfire-daily-report pipeline archive.
A8: 46195 | B8: 25 | C8: 2 | D8: 8786 | E8: 0 | F8: 0 | G8: 3 | H8: 0 | I8: 0 | J8: Backfilled from oregon-wildfire-daily-report pipeline archive.
A9: 46196 | B9: 32 | C9: 1 | D9: 15286 | E9: 0 | F9: 0 | G9: 3 | H9: 0 | I9: 0 | J9: Backfilled from oregon-wildfire-daily-report pipeline archive.
A10: 46197 | B10: 40 | C10: 2 | D10: 14838 | E10: 0 | F10: 0 | G10: 3 | H10: 0 | I10: 0 | J10: Backfilled from oregon-wildfire-daily-report pipeline archive.
A11: 46198 | B11: 37 | C11: 1 | D11: 14838 | E11: 0 | F11: 0 | G11: 0 | H11: 0 | I11: 0 | J11: Backfilled from oregon-wildfire-daily-report pipeline archive.
A12: 46199 | B12: 34 | C12: 0 | D12: 14838 | E12: 0 | F12: 0 | G12: 0 | H12: 0 | I12: 0 | J12: Backfilled from oregon-wildfire-daily-report pipeline archive.
A13: 46200 | B13: 36 | C13: 1 | D13: 15652 | E13: 0 | F13: 0 | G13: 0 | H13: 0 | I13: 0 | J13: Backfilled from oregon-wildfire-daily-report pipeline archive.
... A43: 46230 | B43: 92 | C43: 37 | D43: 1372091 | E43: 98 | F43: 10 | G43: 7487 | H43: 2932 | I43: 2795 | J43: Backfilled from oregon-wildfire-daily-report pipeline archive.

Sheet Summary
B1: Oregon Wildfire Report — Summary
C3: As of | D3: ='Dashboard (2)'!$E$3 -> 46223
C4: Year | D4: =0+'Dashboard (2)'!$B$23 -> 2026
D6: Live stat boxes — mirrors the oregonwildfire.info website hero tiles. Values pull automatically from Dashboard (2) / NWCC Fire Data. Each of the 1D/7D/30D columns shows the change vs. that many days ago, with a sparkline of the last 2 / 7 / 30 logged days underneath. (Columns J onward hold the sparkline source data and are hidden — safe to ignore.)
F8: Trend over prior 1 / 7 / 30 days
D9: Metric | E9: Value | F9: 1D | G9: 7D | H9: 30D
D10: Active Large Fires | E10: ='Dashboard (2)'!$B$10 -> 37 | F10: =IFERROR($E$10-VLOOKUP($D$3-1,DailyLog,3,FALSE),"n/a") -> 8 | G10: =IFERROR($E$10-VLOOKUP($D$3-7,DailyLog,3,FALSE),"n/a") -> 31 | H10: =IFERROR($E$10-VLOOKUP($D$3-30,DailyLog,3,FALSE),"n/a") -> 35
J11: =IFERROR(IF(COUNTA('Daily Metrics Log'!$C$2:$C$2000)-29>=1,INDEX('Daily Metrics Log'!$C$2:$C$2000,COUNTA('Daily Metrics Log'!$C$2:$C$2000)-29),NA()),NA()) -> 1 | K11: =IFERROR(IF(COUNTA('Daily Metrics Log'!$C$2:$C$2000)-28>=1,INDEX('Daily Metrics Log'!$C$2:$C$2000,COUNTA('Daily Metrics Log'!$C$2:$C$2000)-28),NA()),NA()) -> 1 | L11: =IFERROR(IF(COUNTA('Daily Metrics Log'!$C$2:$C$2000)-27>=1,INDEX('Daily Metrics Log'!$C$2:$C$2000,COUNTA('Daily Metrics Log'!$C$2:$C$2000)-27),NA()),NA()) -> 1 | M11: =IFERROR(IF(COUNTA('Daily Metrics Log'!$C$2:$C$2000)-26>=1,INDEX('Daily Metrics Log'!$C$2:$C$2000,COUNTA('Daily Metrics Log'!$C$2:$C$2000)-26),NA()),NA()) -> 2 | N11: =IFERROR(IF(COUNTA('Daily Metrics Log'!$C$2:$C$2000)-25>=1,INDEX('Daily Metrics Log'!$C$2:$C$2000,COUNTA('Daily Metrics Log'!$C$2:$C$2000)-25),NA()),NA()) -> 2 | O11: =IFERROR(IF(COUNTA('Daily Metrics Log'!$C$2:$C$2000)-24>=1,INDEX('Daily Metrics Log'!$C$2:$C$2000,COUNTA('Daily Metrics Log'!$C$2:$C$2000)-24),NA()),NA()) -> 1 | P11: =IFERROR(IF(COUNTA('Daily Metrics Log'!$C$2:$C$2000)-23>=1,INDEX('Daily Metrics Log'!$C$2:$C$2000,COUNTA('Daily Metrics Log'!$C$2:$C$2000)-23),NA()),NA()) -> 0 | Q11: =IFERROR(IF(COUNTA('Daily Metrics Log'!$C$2:$C$2000)-22>=1,INDEX('Daily Metrics Log'!$C$2:$C$2000,COUNTA('Daily Metrics Log'!$C$2:$C$2000)-22),NA()),NA()) -> 3 | R11: =IFERROR(IF(COUNTA('Daily Metrics Log'!$C$2:$C$2000)-21>=1,INDEX('Daily Metrics Log'!$C$2:$C$2000,COUNTA('Daily Metrics Log'!$C$2:$C$2000)-21),NA()),NA()) -> 3 | S11: =IFERROR(IF(COUNTA('Daily Metrics Log'!$C$2:$C$2000)-20>=1,INDEX('Daily Metrics Log'!$C$2:$C$2000,COUNTA('Daily Metrics Log'!$C$2:$C$2000)-20),NA()),NA()) -> 2 | T11: =IFERROR(IF(COUNTA('Daily Metrics Log'!$C$2:$C$2000)-19>=1,INDEX('Daily Metrics Log'!$C$2:$C$2000,COUNTA('Daily Metrics Log'!$C$2:$C$2000)-19),NA()),NA()) -> 2 | U11: =IFERROR(IF(COUNTA('Daily Metrics Log'!$C$2:$C$2000)-18>=1,INDEX('Daily Metrics Log'!$C$2:$C$2000,COUNTA('Daily Metrics Log'!$C$2:$C$2000)-18),NA()),NA()) -> 7 | V11: =IFERROR(IF(COUNTA('Daily Metrics Log'!$C$2:$C$2000)-17>=1,INDEX('Daily Metrics Log'!$C$2:$C$2000,COUNTA('Daily Metrics Log'!$C$2:$C$2000)-17),NA()),NA()) -> 5 | W11: =IFERROR(IF(COUNTA('Daily Metrics Log'!$C$2:$C$2000)-16>=1,INDEX('Daily Metrics Log'!$C$2:$C$2000,COUNTA('Daily Metrics Log'!$C$2:$C$2000)-16),NA()),NA()) -> 6 | X11: =IFERROR(IF(COUNTA('Daily Metrics Log'!$C$2:$C$2000)-15>=1,INDEX('Daily Metrics Log'!$C$2:$C$2000,COUNTA('Daily Metrics Log'!$C$2:$C$2000)-15),NA()),NA()) -> 6 | Y11: =IFERROR(IF(COUNTA('Daily Metrics Log'!$C$2:$C$2000)-14>=1,INDEX('Daily Metrics Log'!$C$2:$C$2000,COUNTA('Daily Metrics Log'!$C$2:$C$2000)-14),NA()),NA()) -> 6 | Z11: =IFERROR(IF(COUNTA('Daily Metrics Log'!$C$2:$C$2000)-13>=1,INDEX('Daily Metrics Log'!$C$2:$C$2000,COUNTA('Daily Metrics Log'!$C$2:$C$2000)-13),NA()),NA()) -> 5 | AA11: =IFERROR(IF(COUNTA('Daily Metrics Log'!$C$2:$C$2000)-12>=1,INDEX('Daily Metrics Log'!$C$2:$C$2000,COUNTA('Daily Metrics Log'!$C$2:$C$2000)-12),NA()),NA()) -> 5 | AB11: =IFERROR(IF(COUNTA('Daily Metrics Log'!$C$2:$C$2000)-11>=1,INDEX('Daily Metrics Log'!$C$2:$C$2000,COUNTA('Daily Metrics Log'!$C$2:$C$2000)-11),NA()),NA()) -> 13 | AC11: =IFERROR(IF(COUNTA('Daily Metrics Log'!$C$2:$C$2000)-10>=1,INDEX('Daily Metrics Log'!$C$2:$C$2000,COUNTA('Daily Metrics Log'!$C$2:$C$2000)-10),NA()),NA()) -> 27 | AD11: =IFERROR(IF(COUNTA('Daily Metrics Log'!$C$2:$C$2000)-9>=1,INDEX('Daily Metrics Log'!$C$2:$C$2000,COUNTA('Daily Metrics Log'!$C$2:$C$2000)-9),NA()),NA()) -> 32 | AE11: =IFERROR(IF(COUNTA('Daily Metrics Log'!$C$2:$C$2000)-8>=1,INDEX('Daily Metrics Log'!$C$2:$C$2000,COUNTA('Daily Metrics Log'!$C$2:$C$2000)-8),NA()),NA()) -> 29 | AF11: =IFERROR(IF(COUNTA('Daily Metrics Log'!$C$2:$C$2000)-7>=1,INDEX('Daily Metrics Log'!$C$2:$C$2000,COUNTA('Daily Metrics Log'!$C$2:$C$2000)-7),NA()),NA()) -> 22 | AG11: =IFERROR(IF(COUNTA('Daily Metrics Log'!$C$2:$C$2000)-6>=1,INDEX('Daily Metrics Log'!$C$2:$C$2000,COUNTA('Daily Metrics Log'!$C$2:$C$2000)-6),NA()),NA()) -> 22 | AH11: =IFERROR(IF(COUNTA('Daily Metrics Log'!$C$2:$C$2000)-5>=1,INDEX('Daily Metrics Log'!$C$2:$C$2000,COUNTA('Daily Metrics Log'!$C$2:$C$2000)-5),NA()),NA()) -> 23 | AI11: =IFERROR(IF(COUNTA('Daily Metrics Log'!$C$2:$C$2000)-4>=1,INDEX('Daily Metrics Log'!$C$2:$C$2000,COUNTA('Daily Metrics Log'!$C$2:$C$2000)-4),NA()),NA()) -> 25 | AJ11: =IFERROR(IF(COUNTA('Daily Metrics Log'!$C$2:$C$2000)-3>=1,INDEX('Daily Metrics Log'!$C$2:$C$2000,COUNTA('Daily Metrics Log'!$C$2:$C$2000)-3),NA()),NA()) -> 27 | AK11: =IFERROR(IF(COUNTA('Daily Metrics Log'!$C$2:$C$2000)-2>=1,INDEX('Daily Metrics Log'!$C$2:$C$2000,COUNTA('Daily Metrics Log'!$C$2:$C$2000)-2),NA()),NA()) -> 35 | AL11: =IFERROR(IF(COUNTA('Daily Metrics Log'!$C$2:$C$2000)-1>=1,INDEX('Daily Metrics Log'!$C$2:$C$2000,COUNTA('Daily Metrics Log'!$C$2:$C$2000)-1),NA()),NA()) -> 37 | AM11: =IFERROR(IF(COUNTA('Daily Metrics Log'!$C$2:$C$2000)-0>=1,INDEX('Daily Metrics Log'!$C$2:$C$2000,COUNTA('Daily Metrics Log'!$C$2:$C$2000)-0),NA()),NA()) -> 37
D12: Total Acres YTD (Large Fires) | E12: ='Dashboard (2)'!$F$69 -> 1368590 | F12: =IFERROR($E$12-VLOOKUP($D$3-1,DailyLog,4,FALSE),"n/a") -> 1117126 | G12: =IFERROR($E$12-VLOOKUP($D$3-7,DailyLog,4,FALSE),"n/a") -> 1334739 | H12: =IFERROR($E$12-VLOOKUP($D$3-30,DailyLog,4,FALSE),"n/a") -> 1359804
J13: =IFERROR(IF(COUNTA('Daily Metrics Log'!$D$2:$D$2000)-29>=1,INDEX('Daily Metrics Log'!$D$2:$D$2000,COUNTA('Daily Metrics Log'!$D$2:$D$2000)-29),NA()),NA()) -> 14938 | K13: =IFERROR(IF(COUNTA('Daily Metrics Log'!$D$2:$D$2000)-28>=1,INDEX('Daily Metrics Log'!$D$2:$D$2000,COUNTA('Daily Metrics Log'!$D$2:$D$2000)-28),NA()),NA()) -> 14838 | L13: =IFERROR(IF(COUNTA('Daily Metrics Log'!$D$2:$D$2000)-27>=1,INDEX('Daily Metrics Log'!$D$2:$D$2000,COUNTA('Daily Metrics Log'!$D$2:$D$2000)-27),NA()),NA()) -> 14838 | M13: =IFERROR(IF(COUNTA('Daily Metrics Log'!$D$2:$D$2000)-26>=1,INDEX('Daily Metrics Log'!$D$2:$D$2000,COUNTA('Daily Metrics Log'!$D$2:$D$2000)-26),NA()),NA()) -> 15278 | N13: =IFERROR(IF(COUNTA('Daily Metrics Log'!$D$2:$D$2000)-25>=1,INDEX('Daily Metrics Log'!$D$2:$D$2000,COUNTA('Daily Metrics Log'!$D$2:$D$2000)-25),NA()),NA()) -> 18029 | O13: =IFERROR(IF(COUNTA('Daily Metrics Log'!$D$2:$D$2000)-24>=1,INDEX('Daily Metrics Log'!$D$2:$D$2000,COUNTA('Daily Metrics Log'!$D$2:$D$2000)-24),NA()),NA()) -> 18029 | P13: =IFERROR(IF(COUNTA('Daily Metrics Log'!$D$2:$D$2000)-23>=1,INDEX('Daily Metrics Log'!$D$2:$D$2000,COUNTA('Daily Metrics Log'!$D$2:$D$2000)-23),NA()),NA()) -> 18029 | Q13: =IFERROR(IF(COUNTA('Daily Metrics Log'!$D$2:$D$2000)-22>=1,INDEX('Daily Metrics Log'!$D$2:$D$2000,COUNTA('Daily Metrics Log'!$D$2:$D$2000)-22),NA()),NA()) -> 19917 | R13: =IFERROR(IF(COUNTA('Daily Metrics Log'!$D$2:$D$2000)-21>=1,INDEX('Daily Metrics Log'!$D$2:$D$2000,COUNTA('Daily Metrics Log'!$D$2:$D$2000)-21),NA()),NA()) -> 23310 | S13: =IFERROR(IF(COUNTA('Daily Metrics Log'!$D$2:$D$2000)-20>=1,INDEX('Daily Metrics Log'!$D$2:$D$2000,COUNTA('Daily Metrics Log'!$D$2:$D$2000)-20),NA()),NA()) -> 24060 | T13: =IFERROR(IF(COUNTA('Daily Metrics Log'!$D$2:$D$2000)-19>=1,INDEX('Daily Metrics Log'!$D$2:$D$2000,COUNTA('Daily Metrics Log'!$D$2:$D$2000)-19),NA()),NA()) -> 25128 | U13: =IFERROR(IF(COUNTA('Daily Metrics Log'!$D$2:$D$2000)-18>=1,INDEX('Daily Metrics Log'!$D$2:$D$2000,COUNTA('Daily Metrics Log'!$D$2:$D$2000)-18),NA()),NA()) -> 27641 | V13: =IFERROR(IF(COUNTA('Daily Metrics Log'!$D$2:$D$2000)-17>=1,INDEX('Daily Metrics Log'!$D$2:$D$2000,COUNTA('Daily Metrics Log'!$D$2:$D$2000)-17),NA()),NA()) -> 27693 | W13: =IFERROR(IF(COUNTA('Daily Metrics Log'!$D$2:$D$2000)-16>=1,INDEX('Daily Metrics Log'!$D$2:$D$2000,COUNTA('Daily Metrics Log'!$D$2:$D$2000)-16),NA()),NA()) -> 28851 | X13: =IFERROR(IF(COUNTA('Daily Metrics Log'!$D$2:$D$2000)-15>=1,INDEX('Daily Metrics Log'!$D$2:$D$2000,COUNTA('Daily Metrics Log'!$D$2:$D$2000)-15),NA()),NA()) -> 30838 | Y13: =IFERROR(IF(COUNTA('Daily Metrics Log'!$D$2:$D$2000)-14>=1,INDEX('Daily Metrics Log'!$D$2:$D$2000,COUNTA('Daily Metrics Log'!$D$2:$D$2000)-14),NA()),NA()) -> 33851 | Z13: =IFERROR(IF(COUNTA('Daily Metrics Log'!$D$2:$D$2000)-13>=1,INDEX('Daily Metrics Log'!$D$2:$D$2000,COUNTA('Daily Metrics Log'!$D$2:$D$2000)-13),NA()),NA()) -> 34720 | AA13: =IFERROR(IF(COUNTA('Daily Metrics Log'!$D$2:$D$2000)-12>=1,INDEX('Daily Metrics Log'!$D$2:$D$2000,COUNTA('Daily Metrics Log'!$D$2:$D$2000)-12),NA()),NA()) -> 37481 | AB13: =IFERROR(IF(COUNTA('Daily Metrics Log'!$D$2:$D$2000)-11>=1,INDEX('Daily Metrics Log'!$D$2:$D$2000,COUNTA('Daily Metrics Log'!$D$2:$D$2000)-11),NA()),NA()) -> 51315 | AC13: =IFERROR(IF(COUNTA('Daily Metrics Log'!$D$2:$D$2000)-10>=1,INDEX('Daily Metrics Log'!$D$2:$D$2000,COUNTA('Daily Metrics Log'!$D$2:$D$2000)-10),NA()),NA()) -> 93765 | AD13: =IFERROR(IF(COUNTA('Daily Metrics Log'!$D$2:$D$2000)-9>=1,INDEX('Daily Metrics Log'!$D$2:$D$2000,COUNTA('Daily Metrics Log'!$D$2:$D$2000)-9),NA()),NA()) -> 177264 | AE13: =IFERROR(IF(COUNTA('Daily Metrics Log'!$D$2:$D$2000)-8>=1,INDEX('Daily Metrics Log'!$D$2:$D$2000,COUNTA('Daily Metrics Log'!$D$2:$D$2000)-8),NA()),NA()) -> 251464 | AF13: =IFERROR(IF(COUNTA('Daily Metrics Log'!$D$2:$D$2000)-7>=1,INDEX('Daily Metrics Log'!$D$2:$D$2000,COUNTA('Daily Metrics Log'!$D$2:$D$2000)-7),NA()),NA()) -> 371077 | AG13: =IFERROR(IF(COUNTA('Daily Metrics Log'!$D$2:$D$2000)-6>=1,INDEX('Daily Metrics Log'!$D$2:$D$2000,COUNTA('Daily Metrics Log'!$D$2:$D$2000)-6),NA()),NA()) -> 368661 | AH13: =IFERROR(IF(COUNTA('Daily Metrics Log'!$D$2:$D$2000)-5>=1,INDEX('Daily Metrics Log'!$D$2:$D$2000,COUNTA('Daily Metrics Log'!$D$2:$D$2000)-5),NA()),NA()) -> 449322 | AI13: =IFERROR(IF(COUNTA('Daily Metrics Log'!$D$2:$D$2000)-4>=1,INDEX('Daily Metrics Log'!$D$2:$D$2000,COUNTA('Daily Metrics Log'!$D$2:$D$2000)-4),NA()),NA()) -> 498376 | AJ13: =IFERROR(IF(COUNTA('Daily Metrics Log'!$D$2:$D$2000)-3>=1,INDEX('Daily Metrics Log'!$D$2:$D$2000,COUNTA('Daily Metrics Log'!$D$2:$D$2000)-3),NA()),NA()) -> 550472 | AK13: =IFERROR(IF(COUNTA('Daily Metrics Log'!$D$2:$D$2000)-2>=1,INDEX('Daily Metrics Log'!$D$2:$D$2000,COUNTA('Daily Metrics Log'!$D$2:$D$2000)-2),NA()),NA()) -> 669927 | AL13: =IFERROR(IF(COUNTA('Daily Metrics Log'!$D$2:$D$2000)-1>=1,INDEX('Daily Metrics Log'!$D$2:$D$2000,COUNTA('Daily Metrics Log'!$D$2:$D$2000)-1),NA()),NA()) -> 1053674 | AM13: =IFERROR(IF(COUNTA('Daily Metrics Log'!$D$2:$D$2000)-0>=1,INDEX('Daily Metrics Log'!$D$2:$D$2000,COUNTA('Daily Metrics Log'!$D$2:$D$2000)-0),NA()),NA()) -> 1372091
D14: Active Fires (WF + RX) | E14: ='Dashboard (2)'!$E$4 -> 89 | F14: =IFERROR($E$14-VLOOKUP($D$3-1,DailyLog,2,FALSE),"n/a") -> -12 | G14: =IFERROR($E$14-VLOOKUP($D$3-7,DailyLog,2,FALSE),"n/a") -> 47 | H14: =IFERROR($E$14-VLOOKUP($D$3-30,DailyLog,2,FALSE),"n/a") -> 66
